Workbook

Sheet Guide
A1: DBIZ2 · Session 7 — Workshop workbook
A3: PURPOSE | B3: One sheet per workshop block (W0–W5). Each sheet's output is the next sheet's input, wired with real formulas. Nothing is retyped between sheets.
A4: ADD / REMOVE | B4: Every table has spare rows and every formula spans the whole table, so adding or deleting a function anywhere updates the rest of the workbook automatically. Type into the next blank row; clear a row to delete it. Do not delete whole spreadsheet rows.
A5: IF A FORMULA BREAKS | B5: Never type into a green or black cell. If you do, clear it and copy the formula down from the row above. The integrity line at the bottom of W1 reports any row that lost its Base hours formula.
A6: SEED DATA | B6: A small worked example ships with the workbook — LabDesk, a computer-lab reservation system, with three features. Teams clear it and enter their own project.
A8: Data chain
A9: Sheet | B9: Block | C9: Input taken from | D9: Output flowing out | E9: Cells the team fills | F9: Owner
A10: Parameters | B10: before the session | C10: Rates, factors, capacity, thresholds set by the lecturer | D10: Every derived number in W1, W2, W4, W5 | E10: All yellow cells | F10: Lecturer
A11: W0_Scope | B11: W0 | C11: Use Case Diagram; CVCA; Context Diagram | D11: Feature list → W1; data functions → FP count; Won't-have → W5 | E11: Tables 1–4 | F11: Whole team
A12: W1_FunctionList | B12: W1 | C12: Features from W0; the five design diagrams | D12: L2 and L3 rows → W2_Costing and W4 | E12: Columns A–J, L–N | F12: Feature owners
A13: W2_Costing | B13: W2 | C13: W1 rows; Parameters | D13: Cost per L3 and per L2; function-point cross-check → W2_Rollup | E13: Nothing — fully derived | F13: —
A14: W2_Rollup | B14: W2 | C14: W2_Costing | D14: Machine signals → W3; three headline figures → W5 | E14: Three shared observations | F14: Integrator
A15: W3_CrossReview | B15: W3 | C15: Machine signals from W2_Rollup | D15: Defect log → W4 buckets | E15: Blue = owning team · Orange = reviewing team | F15: Two teams
A16: W4_Prioritization | B16: W4 | C16: Initial priority from W1; defects from W3 | D16: Effective priority → back into W2_Costing | E16: Rule, Kano, new priority, justification | F16: Whole team
A17: W5_Handover | B17: W5 | C17: Three figures from W2_Rollup; Parameters | D17: business-case.md, tasks.md, Session 8 | E17: Open questions and notes | F17: Integrator
A19: Colour convention
A20: Blue text | B20: A cell you type into
A21: Black text | B21: A formula computed inside this sheet — do not overwrite
A22: Green text | B22: A formula pulling from another sheet — do not overwrite
A23: Yellow fill | B23: A cell that must be filled in
A24: Light blue fill | B24: Filled by the OWNING team (W3 only)
A25: Orange fill | B25: Filled by the REVIEWING team (W3 only)
A27: Three rules said out loud
A28: 1. One diagram per sweep. Mixing diagrams destroys the source trail — for people and for AI alike.
A29: 2. Cut by lowering priority, never by lowering effort.
A30: 3. Green cells and the whole W2 block are derived views. If a number looks wrong, fix the source and recalculate.

Sheet Parameters
A1: Parameters — Fixed for the whole class
A3: INPUT | B3: Labour-market data, productivity assumptions and the team capacity, fixed for the whole cohort.
A4: OUTPUT | B4: Every derived number in W1, W2, W4 and W5 traces back to a cell on this sheet.
A5: WHY FIXED | B5: If each team invented its own rates the exercise would test guessing rather than the model, and results would not be comparable at marking. The point of a published parameter is that the subjectivity sits in ONE auditable place instead of forty scattered ones.
A7: 1. Effort size to base hours (applied at level 3)
A8: Size | B8: Hours | D8: Note
A9: S | B9: 4 | D9: Ceiling for one L3 row is 16 h — above that it is not yet an L3 row
A10: M | B10: 8 | D10: Matches the test: ask a developer; an answer of 4–16 h is correct granularity
A11: L | B11: 16
A13: 2. Technical layer to AI leverage and default seniority
A14: Layer | B14: AI leverage factor | C14: Default band | D14: Note
A15: FE | B15: 0.35 | C15: Junior | D15: Screens, forms, repeated patterns — AI generates these well
A16: BE | B16: 0.7 | C16: Senior | D16: Business logic, state, concurrency
A17: INT | B17: 1 | C17: Senior | D17: Third-party APIs, credentials, sandboxes — AI helps least here
A19: 3. Hourly cost by seniority band (VND / hour)
A20: Band | B20: Rate | D20: Source
A21: Junior | B21: 200000 | D21: ITviec 2025-26 median 25.35m VND/month x 1.35 overhead / 176 h
A22: Senior | B22: 300000 | D22: ITviec 2025-26 median 39.9m VND/month x 1.35 / 176 h
A23: Expert | B23: 400000 | D23: ITviec 2025-26 median 54.9m VND/month x 1.35 / 176 h
A25: 4. Verification factor (driven by acceptance-criterion quality)
A26: EARS precise? | B26: Factor | D26: Note
A27: Yes | B27: 0.15 | D27: Clear criteria — fast to verify, often automatable
A28: No | B28: 0.4 | D28: Vague criteria — a person must reason the answer out from scratch
A30: 5. Function point weights (IFPUG average complexity)
A31: FP type | B31: Weight | D31: What it counts
A32: EI | B32: 4 | D32: External Input — data crosses the boundary inward and changes stored data
A33: EO | B33: 5 | D33: External Output — data leaves the boundary WITH derived values or calculation
A34: EQ | B34: 4 | D34: External inQuiry — retrieval only, no derived data, nothing stored changes
A35: ILF | B35: 10 | D35: Internal Logical File — a group of data the system itself maintains
A36: EIF | B36: 7 | D36: External Interface File — data the system reads but never maintains
A37: NC | B37: 0 | D37: Not countable — a business rule or non-functional item inside another transaction
A38: Hours per unadjusted function point | B38: 3 | D38: Class parameter, PRE-AI gross hours. Published industry figures range very widely; calibrate this from your own delivered projects rather than importing a benchmark
A41: 6. Team capacity for DBIZ3
A42: Team members | B42: 6
A43: Weeks | B43: 12
A44: Productive hours per person per week | B44: 5 | D44: Hours actually spent building, not hours present
A45: Total capacity (person-hours) | B45: =B42*B43*B44 -> 360 | D45: Hard ceiling for the whole scope: Must + Should + Could
A47: 7. Thresholds
A48: Must, maximum share of scope effort | B48: 0.6 | D48: DSDM: above 60% the project enters the risk zone
A49: Could, target share of scope effort | B49: 0.2 | D49: The contingency pool, expressed as scope rather than money
...

Sheet W0_Scope
A1: W0 — Establish scope and split into features
A3: INPUT | B3: The Use Case Diagram, the CVCA and the Context Diagram, updated after the user meeting. Every diagram element must already carry an ID.
A4: OUTPUT | B4: (a) a complete use-case inventory, (b) a small set of features, each a folder under specs/, (c) an explicit Won't-have list, (d) the data functions the system maintains or reads. Feature IDs feed column A of W1.
A5: PROCEDURE | B5: 1. List EVERY use case in Table 1 — names only, no discussion yet. 2. Cluster them into features in Table 2. A feature name is a business noun the client recognises, never a screen name or a technical module. 3. Coverage check against the CVCA: every primary actor must be served by at least one feature. 4. Record anything excluded in Table 3, with the reason. 5. In Table 4, list the data the system MAINTAINS (ILF) and the data it only READS from another system (EIF). Read these off the Context Diagram boundary.
A6: RULE | B6: Merge any feature expected to hold fewer than 3 L2 rows. A feature that no use case and no CVCA flow points at does not belong in the release.
A8: Table 1 · Use case inventory — list every use case before clustering
A9: Use case ID | B9: Use case name | C9: Primary actor | D9: Assigned feature | E9: Login required
A10: UC-01 | B10: View book shelf location | C10: Reader | D10: F-01 | E10: No
A11: UC-02 | B11: Browse interactive digital library map | C11: Reader | D11: F-01 | E11: No
A12: UC-03 | B12: Filter books by access format (online, physical or both) | C12: Reader | D12: F-03 | E12: No
A13: UC-04 | B13: Write, edit and delete own book reviews | C13: Reader | D13: F-02 | E13: Yes
A14: UC-05 | B14: View book reviews | C14: Reader | D14: F-02 | E14: No
A15: UC-06 | B15: Access book information and reviews via QR code (physical books; reviews via UC-04) | C15: Reader | D15: F-02 | E15: No
A16: UC-07 | B16: Update and view personal reading history and preferences | C16: Reader | D16: F-03 | E16: Yes
A17: UC-08 | B17: AI-based conversational book search | C17: Reader | D17: F-03 | E17: Yes
A18: UC-09 | B18: Automatic personalised book recommendations | C18: Reader | D18: F-03 | E18: Yes
A19: UC-10 | B19: Print QR code labels for physical books (QR codes are generated automatically) | C19: On-site Staff | D19: F-02 | E19: Staff login
A20: UC-11 | B20: Register and sign in (library card with email OTP) | C20: Reader | D20: F-04 | E20: No
... A23: UC-14 | B23: Report a review that violates rules | C23: Reader | D23: F-02 | E23: Yes
A27: Table 2 · Feature list — this is what flows into W1
A28: Feature ID | B28: Feature name (business noun) | C28: Scope in one sentence | D28: Primary actors served | E28: Owner | F28: Use cases covered
A29: F-01 | B29: Book Location & Library Map | C29: Readers see the exact shelf location of each book and browse a digital map of floors and reading rooms. | D29: Reader | E29: Owner A | F29: UC-01, UC-02
A30: F-02 | B30: Reviews & QR | C30: Readers write, edit, delete and read reviews of books, including by scanning a QR code on a physical book, and On-site Staff print the QR labels and remove reviews that violate rules. | D30: Reader, On-site Staff | E30: Owner C | F30: UC-04, UC-05, UC-06, UC-10, UC-13, UC-14
A31: F-03 | B31: Discovery, Reading History & Recommendation | C31: Readers filter books by access format (online, physical or both), keep a reading history and a saved-books list, and get AI chatbot search and recommendations based on their preferences. | D31: Reader | E31: Owner D | F31: UC-03, UC-07, UC-08, UC-09, UC-12
A32: F-04 | B32: Platform, Access & Operations | C32: Readers sign in (library card with email OTP), On-site Staff sign in with their internal library accounts to reach their minimal page, and the platform syncs data from the library's internal system, is deployed and keeps an audit log. | D32: All actors | E32: Owner A | F32: UC-11
A41: Feature count | B41: =COUNTA(A29:A40) -> 4 | C41: =IF(AND(B41>=Parameters!$B$52,B41<=Parameters!$B$53),"PASS","REVIEW — outside "&Parameters!$B$52&"-"&Parameters!$B$53) -> PASS
A43: Table 3 · Won't-have — record it here, never drop it silently
A44: Excluded from scope | B44: How it surfaced | C44: Reason for exclusion
A45: Automatic tracking of reading progress and finished books | B45: Stated in the note under UC-07 | C45: The library records borrow/return of physical books but not pages read. Online books opened by library card readers and borrowed physical books enter the history automatically; readers mark Reading or Finished and enter progress manually in release 1
A46: Borrowing, returning and renewing loans | B46: Implied by former UC-05 ('ready for borrowing', removed from the diagram); no loan use case in the diagram | C46: Stays in the library's internal system; this platform does not handle loans. The current OPAC already shows copy availability and the Borrow action
A47: Reading online content inside the platform | B47: Implied by UC-03 (Online format); no viewer use case in the diagram | C47: Confirmed: online books can be opened or downloaded without sign-in on the existing OPAC; this platform builds no viewer and no download of its own
A48: Assigning or editing shelf codes and the library layout | B48: Implied by the original UC-01 (Manage book locations) | C48: Done in the library's internal system; this platform only reads the data and publishes it to readers
A49: Full librarian/admin workspace in the OPAC | B49: Implied by the original actor Librarian/Admin | C49: Staff use only a minimal page (QR label printing, review removal) with their internal accounts; catalogue, shelf codes and loans are managed in the internal system
A50: Traditional keyword search | B50: Not in any use case | C50: Already provided by the current OPAC; this platform adds filtering and AI chatbot search only
A51: QR codes for online-only books | B51: Business rule on UC-06 | C51: Online-only books have no physical copy to attach a QR code to; readers download the PDF instead
A52: Sending reader reviews and feedback to the library's internal system, or a report/dashboard of them for library staff | B52: Implied by the CVCA flow 'reader feedback & rate books' to the library (flow to be removed from the CVCA) | C52: Reviews and feedback stay in this platform and are not sent to the internal system
A53: Screen for library staff to edit floor plans and rooms | B53: Implied by UC-02 (digital library map) | C53: No digital floor plan exists today; the team prepares it once. Changes to the room layout are made by the team, not through a screen in release 1
A54: Features not rebuilt: (a) like/dislike rating, list of books in a room, copy availability and borrow status, already on the current OPAC; (b) viewing and filtering by collection status (In collection / Coming soon) | B54: (a) Confirmed on the current OPAC (document location panel shows each copy, its circulation point and status); (b) former UC-03, dropped after team review | C54: (a) Not rebuilt. This platform keeps text reviews only and does not read copy circulation status. (b) The internal system holds the field, but readers do not need it on the web
A55: Showing the access format of each book on the book detail page (FR-03-14) and downloading PDFs on this platform (FR-03-15) | B55: Scope cut after the W4 capacity review (UC-03 reduced to the access-format filter) | C55: Download PDF: the current OPAC already has this function and online books can be downloaded without sign-in, so it is not rebuilt. Access format display: for physical books the OPAC already shows the number of copies and the shelf location; for online books it already shows a download button. This platform only adds the online / physical / both filter (FR-03-12)
... A57: Error tracking, health check and alerts to the project team (FR-04-15) | B57: Hidden work in F-04, cut after the W4 capacity review | C57: Deferred to fit team capacity; the team checks the system by hand in release 1
...

Sheet W1_FunctionList
A1: W1 — Decompose features into the function list
A3: INPUT | B3: The feature list from W0 and the five design diagrams: Use Case, Sequence, Context (DFD L0), CVCA, Architecture + ADR.
A4: OUTPUT | B4: Every function at two levels. L2 = a business behaviour the client signs off, carrying the EARS criterion and the function-point type. L3 = one work item in one technical layer. No money on this sheet.
A5: PROCEDURE | B5: 1. Sweep the five diagrams, ONE DIAGRAM PER PASS. Record every candidate with the diagram element it came from. 2. Merge duplicates — keep one row, accumulate the sources in column E. 3. Write one EARS sentence per L2 row. 4. Classify each L2 row by function-point type: EI, EO, EQ, or NC when it is a rule or a non-functional item living inside another transaction. 5. Split each L2 into L3 rows by layer (FE / BE / INT) and give each a size. 6. Set an initial MoSCoW priority by instinct. W4 is where it is tightened.
A6: WATCH FOR | B6: Many valuable rows are NC — 'prevent double booking', 'enforce authorisation', 'deploy automatically'. They score zero function points and are often the most expensive rows in the sheet. That gap is the reason the function-point count is a CROSS-CHECK, never the estimate itself.
A7: ADD / REMOVE | B7: Type into the next blank row to add a function; clear a row's contents to remove it. Every other sheet follows automatically.
A9: Feature | B9: L2 ID | C9: L2 function name | D9: Actor | E9: EARS acceptance criterion | F9: Source trace | G9: Dependency | H9: Initial priority | I9: FP type | J9: L3 ID | K9: Layer | L9: L3 work item | M9: Size | N9: Base hours | O9: EARS precise? | P9: Hidden work? | Q9: New L2 | R9: L2 index | S9: FP value
A10: F-01 | B10: FR-01-01 | C10: View book shelf location | D10: System | E10: WHEN a reader opens a book detail page, the system SHALL display the floor, room and shelf code where the book is placed. | F10: UC:UC-01; DFD L0: Book placement & library layout (EIF) | G10: – | H10: Must | I10: EQ | J10: FR-01-01-FE | K10: FE | L10: Screen: shelf location panel on the book detail page | M10: S | N10: {=IF(M10="","",IFERROR(INDEX(Parameters!$B$9:$B$11,MATCH(M10,Parameters!$A$9:$A$11,0)),"?"))} -> 4 | O10: Yes | P10: No | Q10: =IF(B10="","",IF(B10<>B9,1,0)) -> 1 | R10: =IF(B10="","",SUM($Q$10:Q10)) -> 1 | S10: {=IF(Q10=1,IFERROR(INDEX(Parameters!$B$32:$B$37,MATCH(I10,Parameters!$A$32:$A$37,0)),0),0)} -> 4
A11: F-01 | B11: FR-01-01 | C11: View book shelf location | D11: System | E11: WHEN a reader opens a book detail page, the system SHALL display the floor, room and shelf code where the book is placed. | F11: UC:UC-01; DFD L0: Book placement & library layout (EIF) | G11: FR-01-01 | H11: Must | I11: EQ | J11: FR-01-01-BE | K11: BE | L11: API: get floor, room and shelf code by book ID | M11: S | N11: {=IF(M11="","",IFERROR(INDEX(Parameters!$B$9:$B$11,MATCH(M11,Parameters!$A$9:$A$11,0)),"?"))} -> 4 | O11: Yes | P11: No | Q11: =IF(B11="","",IF(B11<>B10,1,0)) -> 0 | R11: =IF(B11="","",SUM($Q$10:Q11)) -> 1 | S11: {=IF(Q11=1,IFERROR(INDEX(Parameters!$B$32:$B$37,MATCH(I11,Parameters!$A$32:$A$37,0)),0),0)} -> 0
A12: F-01 | B12: FR-01-02 | C12: Browse the digital library map | D12: System | E12: WHEN a reader opens the library map, the system SHALL display the floors and the reading rooms of each floor. | F12: UC:UC-02; DFD L0: Book placement & library layout (EIF) | G12: FR-01-01 | H12: Must | I12: EQ | J12: FR-01-02-FE | K12: FE | L12: Screen: interactive floor plan with floor switcher and clickable rooms | M12: L | N12: {=IF(M12="","",IFERROR(INDEX(Parameters!$B$9:$B$11,MATCH(M12,Parameters!$A$9:$A$11,0)),"?"))} -> 16 | O12: Yes | P12: No | Q12: =IF(B12="","",IF(B12<>B11,1,0)) -> 1 | R12: =IF(B12="","",SUM($Q$10:Q12)) -> 2 | S12: {=IF(Q12=1,IFERROR(INDEX(Parameters!$B$32:$B$37,MATCH(I12,Parameters!$A$32:$A$37,0)),0),0)} -> 4
A13: F-01 | B13: FR-01-02 | C13: Browse the digital library map | D13: System | E13: WHEN a reader opens the library map, the system SHALL display the floors and the reading rooms of each floor. | F13: UC:UC-02; DFD L0: Book placement & library layout (EIF) | G13: FR-01-02 | H13: Must | I13: EQ | J13: FR-01-02-BE | K13: BE | L13: API: list floors and rooms | M13: S | N13: {=IF(M13="","",IFERROR(INDEX(Parameters!$B$9:$B$11,MATCH(M13,Parameters!$A$9:$A$11,0)),"?"))} -> 4 | O13: Yes | P13: No | Q13: =IF(B13="","",IF(B13<>B12,1,0)) -> 0 | R13: =IF(B13="","",SUM($Q$10:Q13)) -> 2 | S13: {=IF(Q13=1,IFERROR(INDEX(Parameters!$B$32:$B$37,MATCH(I13,Parameters!$A$32:$A$37,0)),0),0)} -> 0
A14: F-01 | B14: FR-01-03 | C14: Show a book's room on the map | D14: System | E14: WHEN a reader selects the map link on a book shelf location, the system SHALL open the library map with the room that holds the book highlighted. | F14: UC:UC-01; UC:UC-02 | G14: FR-01-02 | H14: Should | I14: EQ | J14: FR-01-03-FE | K14: FE | L14: Screen: map view with highlighted room and deep link from book detail | M14: M | N14: {=IF(M14="","",IFERROR(INDEX(Parameters!$B$9:$B$11,MATCH(M14,Parameters!$A$9:$A$11,0)),"?"))} -> 8 | O14: Yes | P14: No | Q14: =IF(B14="","",IF(B14<>B13,1,0)) -> 1 | R14: =IF(B14="","",SUM($Q$10:Q14)) -> 3 | S14: {=IF(Q14=1,IFERROR(INDEX(Parameters!$B$32:$B$37,MATCH(I14,Parameters!$A$32:$A$37,0)),0),0)} -> 4
A15: F-01 | B15: FR-01-03 | C15: Show a book's room on the map | D15: System | E15: WHEN a reader selects the map link on a book shelf location, the system SHALL open the library map with the room that holds the book highlighted. | F15: UC:UC-01; UC:UC-02 | G15: FR-01-03 | H15: Should | I15: EQ | J15: FR-01-03-BE | K15: BE | L15: API: return room map coordinates with the shelf location | M15: S | N15: {=IF(M15="","",IFERROR(INDEX(Parameters!$B$9:$B$11,MATCH(M15,Parameters!$A$9:$A$11,0)),"?"))} -> 4 | O15: Yes | P15: No | Q15: =IF(B15="","",IF(B15<>B14,1,0)) -> 0 | R15: =IF(B15="","",SUM($Q$10:Q15)) -> 3 | S15: {=IF(Q15=1,IFERROR(INDEX(Parameters!$B$32:$B$37,MATCH(I15,Parameters!$A$32:$A$37,0)),0),0)} -> 0
A16: F-01 | B16: FR-01-04 | C16: Prepare the digital floor plan | D16: System | E16: The system SHALL provide a digital floor plan of every floor in which each reading room carries the same room code as the internal library system. | F16: W0 Table 4 note (floor plan is a fixed asset built once by the project team) | G16: FR-01-03 | H16: Must | I16: NC | J16: FR-01-04-FE | K16: FE | L16: Asset: draw the digital floor plan of each floor and tag every room with its room code | M16: L | N16: {=IF(M16="","",IFERROR(INDEX(Parameters!$B$9:$B$11,MATCH(M16,Parameters!$A$9:$A$11,0)),"?"))} -> 16 | O16: Yes | P16: Yes | Q16: =IF(B16="","",IF(B16<>B15,1,0)) -> 1 | R16: =IF(B16="","",SUM($Q$10:Q16)) -> 4 | S16: {=IF(Q16=1,IFERROR(INDEX(Parameters!$B$32:$B$37,MATCH(I16,Parameters!$A$32:$A$37,0)),0),0)} -> 0
A17: F-01 | B17: FR-01-05 | C17: Check room codes against the internal system | D17: System | E17: WHEN a sync run finishes, the system SHALL report every room code on the floor plan that has no matching room code in the synced layout, and every synced room code that has no room on the floor plan. | F17: Derived: W0 Table 4 note (floor plan room codes must match the internal system) | G17: FR-01-04 | H17: Should | I17: NC | J17: FR-01-05-BE | K17: BE | L17: Job: compare synced room codes with floor plan room codes and report mismatches | M17: M | N17: {=IF(M17="","",IFERROR(INDEX(Parameters!$B$9:$B$11,MATCH(M17,Parameters!$A$9:$A$11,0)),"?"))} -> 8 | O17: Yes | P17: Yes | Q17: =IF(B17="","",IF(B17<>B16,1,0)) -> 1 | R17: =IF(B17="","",SUM($Q$10:Q17)) -> 5 | S17: {=IF(Q17=1,IFERROR(INDEX(Parameters!$B$32:$B$37,MATCH(I17,Parameters!$A$32:$A$37,0)),0),0)} -> 0
A18: F-02 | B18: FR-02-01 | C18: Write a book review | D18: System | E18: WHEN a signed-in reader submits a review text for a book, the system SHALL save it against that book and that reader. | F18: UC:UC-04; DFD L0: Book review (ILF) | G18: – | H18: Must | I18: EI | J18: FR-02-01-FE | K18: FE | L18: Screen: review form | M18: S | N18: {=IF(M18="","",IFERROR(INDEX(Parameters!$B$9:$B$11,MATCH(M18,Parameters!$A$9:$A$11,0)),"?"))} -> 4 | O18: Yes | P18: No | Q18: =IF(B18="","",IF(B18<>B17,1,0)) -> 1 | R18: =IF(B18="","",SUM($Q$10:Q18)) -> 6 | S18: {=IF(Q18=1,IFERROR(INDEX(Parameters!$B$32:$B$37,MATCH(I18,Parameters!$A$32:$A$37,0)),0),0)} -> 4
A19: F-02 | B19: FR-02-01 | C19: Write a book review | D19: System | E19: WHEN a signed-in reader submits a review text for a book, the system SHALL save it against that book and that reader. | F19: UC:UC-04; DFD L0: Book review (ILF) | G19: FR-02-01 | H19: Must | I19: EI | J19: FR-02-01-BE | K19: BE | L19: API: validate and save review | M19: S | N19: {=IF(M19="","",IFERROR(INDEX(Parameters!$B$9:$B$11,MATCH(M19,Parameters!$A$9:$A$11,0)),"?"))} -> 4 | O19: Yes | P19: No | Q19: =IF(B19="","",IF(B19<>B18,1,0)) -> 0 | R19: =IF(B19="","",SUM($Q$10:Q19)) -> 6 | S19: {=IF(Q19=1,IFERROR(INDEX(Parameters!$B$32:$B$37,MATCH(I19,Parameters!$A$32:$A$37,0)),0),0)} -> 0
A20: F-02 | B20: FR-02-02 | C20: View book reviews | D20: System | E20: WHEN a reader opens the reviews of a book, the system SHALL display the list of reviews for that book. | F20: UC:UC-05; DFD L0: Book review (ILF) | G20: FR-02-01 | H20: Must | I20: EQ | J20: FR-02-02-FE | K20: FE | L20: Screen: paged review list | M20: M | N20: {=IF(M20="","",IFERROR(INDEX(Parameters!$B$9:$B$11,MATCH(M20,Parameters!$A$9:$A$11,0)),"?"))} -> 8 | O20: Yes | P20: No | Q20: =IF(B20="","",IF(B20<>B19,1,0)) -> 1 | R20: =IF(B20="","",SUM($Q$10:Q20)) -> 7 | S20: {=IF(Q20=1,IFERROR(INDEX(Parameters!$B$32:$B$37,MATCH(I20,Parameters!$A$32:$A$37,0)),0),0)} -> 4
A21: F-02 | B21: FR-02-02 | C21: View book reviews | D21: System | E21: WHEN a reader opens the reviews of a book, the system SHALL display the list of reviews for that book. | F21: UC:UC-05; DFD L0: Book review (ILF) | G21: FR-02-02 | H21: Must | I21: EQ | J21: FR-02-02-BE | K21: BE | L21: API: list reviews with pagination | M21: S | N21: {=IF(M21="","",IFERROR(INDEX(Parameters!$B$9:$B$11,MATCH(M21,Parameters!$A$9:$A$11,0)),"?"))} -> 4 | O21: Yes | P21: No | Q21: =IF(B21="","",IF(B21<>B20,1,0)) -> 0 | R21: =IF(B21="","",SUM($Q$10:Q21)) -> 7 | S21: {=IF(Q21=1,IFERROR(INDEX(Parameters!$B$32:$B$37,MATCH(I21,Parameters!$A$32:$A$37,0)),0),0)} -> 0
... A87: F-04 | B87: FR-04-15 | C87: Monitor errors and availability | D87: System | E87: WHEN the system raises an unhandled error or a health check fails, the system SHALL record the error with its context and notify the project team. | F87: Derived: F-04 scope (operations); hidden technical work | G87: FR-04-14 | H87: Should | I87: NC | J87: FR-04-15-BE | K87: BE | L87: Error tracking, health check and alert to the project team | M87: M | N87: {=IF(M87="","",IFERROR(INDEX(Parameters!$B$9:$B$11,MATCH(M87,Parameters!$A$9:$A$11,0)),"?"))} -> 8 | O87: Yes | P87: Yes | Q87: =IF(B87="","",IF(B87<>B86,1,0)) -> 1 | R87: =IF(B87="","",SUM($Q$10:Q87)) -> 45 | S87: {=IF(Q87=1,IFERROR(INDEX(Parameters!$B$32:$B$37,MATCH(I87,Parameters!$A$32:$A$37,0)),0),0)} -> 0
A88: Totals | C88: ="L2 functions: "&SUM(Q10:Q87)&" | L3 work items: "&COUNTA(J10:J87) -> L2 functions: 45 | L3 work items: 78 | N88: =SUM(N10:N87) -> 532 | S88: =SUM(S10:S87) -> 110
A89: Integrity | C89: =IF(SUMPRODUCT((J10:J87<>"")*(NOT(ISNUMBER(N10:N87))))=0,"All L3 rows have a numeric Base hours value","WARNING: "&SUMPRODUCT((J10:J87<>"")*(NOT(ISNUMBER(N10:N87))))&" row(s) lost the Base hours formula - copy it down from a neighbouring row") -> All L3 rows have a numeric Base hours value

Sheet W2_Rollup
A1: W2 — Roll-up and threshold check
A3: INPUT | B3: W2_Costing, which reads W1 and W4. Nothing is typed here except the three shared observations at the bottom.
A4: OUTPUT | B4: Per-feature totals, the three headline figures for Session 8, and a pass/fail on every threshold — shown twice: as first written in W1, and after the W4 decisions.
A5: PROCEDURE | B5: 1. The integrator merges the branches and commits. 2. Recalculate. Fix nothing yet. 3. Just observe and assess whether the cost analysis is good enough
A7: Per feature (using the effective priority, i.e. after W4)
A8: Feature | B8: Name | C8: L2 | D8: L3 | E8: Base h (in use) | F8: Must (p-h) | G8: Should | H8: Could | I8: Won't | J8: In-scope p-h | K8: In-scope cost | L8: Must % | M8: Bottom-up h | N8: Transactional FP | O8: Bottom-up h per FP
A9: =IF(W0_Scope!A29="","",W0_Scope!A29) -> F-01 | B9: =IF($A9="","",W0_Scope!B29) -> Book Location & Library Map | C9: =IF($A9="","",SUMIF(W1_FunctionList!$A$10:$A$87,$A9,W1_FunctionList!$Q$10:$Q$87)) -> 5 | D9: =IF($A9="","",COUNTIF(W2_Costing!$B$9:$B$128,$A9)) -> #REF! | E9: =IF($A9="","",SUMIF(W2_Costing!$B$9:$B$128,$A9,W2_Costing!$E$9:$E$128)) -> #N/A | F9: =IF($A9="","",SUMIFS(W2_Costing!$J$9:$J$128,W2_Costing!$B$9:$B$128,$A9,W2_Costing!$N$9:$N$128,"Must")) -> #N/A | G9: =IF($A9="","",SUMIFS(W2_Costing!$J$9:$J$128,W2_Costing!$B$9:$B$128,$A9,W2_Costing!$N$9:$N$128,"Should")) -> #N/A | H9: =IF($A9="","",SUMIFS(W2_Costing!$J$9:$J$128,W2_Costing!$B$9:$B$128,$A9,W2_Costing!$N$9:$N$128,"Could")) -> #N/A | I9: =IF($A9="","",SUMIFS(W2_Costing!$J$9:$J$128,W2_Costing!$B$9:$B$128,$A9,W2_Costing!$N$9:$N$128,"Won't")) -> #N/A | J9: =IF($A9="","",F9+G9+H9) -> #N/A | K9: =IF($A9="","",SUMIFS(W2_Costing!$M$9:$M$128,W2_Costing!$B$9:$B$128,$A9)-SUMIFS(W2_Costing!$M$9:$M$128,W2_Costing!$B$9:$B$128,$A9,W2_Costing!$N$9:$N$128,"Won't")) -> #N/A | L9: =IF($A9="","",IF(J9=0,0,F9/J9)) -> #N/A | M9: =IF($A9="","",SUMIF(W1_FunctionList!$A$10:$A$87,$A9,W1_FunctionList!$N$10:$N$87)) -> 64 | N9: =IF($A9="","",SUMIF(W1_FunctionList!$A$10:$A$87,$A9,W1_FunctionList!$S$10:$S$87)) -> 12 | O9: =IF(OR($A9="",N9=0),"",M9/N9) -> 5.3333333
A10: =IF(W0_Scope!A30="","",W0_Scope!A30) -> F-02 | B10: =IF($A10="","",W0_Scope!B30) -> Reviews & QR | C10: =IF($A10="","",SUMIF(W1_FunctionList!$A$10:$A$87,$A10,W1_FunctionList!$Q$10:$Q$87)) -> 10 | D10: =IF($A10="","",COUNTIF(W2_Costing!$B$9:$B$128,$A10)) -> #REF! | E10: =IF($A10="","",SUMIF(W2_Costing!$B$9:$B$128,$A10,W2_Costing!$E$9:$E$128)) -> #N/A | F10: =IF($A10="","",SUMIFS(W2_Costing!$J$9:$J$128,W2_Costing!$B$9:$B$128,$A10,W2_Costing!$N$9:$N$128,"Must")) -> #N/A | G10: =IF($A10="","",SUMIFS(W2_Costing!$J$9:$J$128,W2_Costing!$B$9:$B$128,$A10,W2_Costing!$N$9:$N$128,"Should")) -> #N/A | H10: =IF($A10="","",SUMIFS(W2_Costing!$J$9:$J$128,W2_Costing!$B$9:$B$128,$A10,W2_Costing!$N$9:$N$128,"Could")) -> #N/A | I10: =IF($A10="","",SUMIFS(W2_Costing!$J$9:$J$128,W2_Costing!$B$9:$B$128,$A10,W2_Costing!$N$9:$N$128,"Won't")) -> #N/A | J10: =IF($A10="","",F10+G10+H10) -> #N/A | K10: =IF($A10="","",SUMIFS(W2_Costing!$M$9:$M$128,W2_Costing!$B$9:$B$128,$A10)-SUMIFS(W2_Costing!$M$9:$M$128,W2_Costing!$B$9:$B$128,$A10,W2_Costing!$N$9:$N$128,"Won't")) -> #N/A | L10: =IF($A10="","",IF(J10=0,0,F10/J10)) -> #N/A | M10: =IF($A10="","",SUMIF(W1_FunctionList!$A$10:$A$87,$A10,W1_FunctionList!$N$10:$N$87)) -> 96 | N10: =IF($A10="","",SUMIF(W1_FunctionList!$A$10:$A$87,$A10,W1_FunctionList!$S$10:$S$87)) -> 32 | O10: =IF(OR($A10="",N10=0),"",M10/N10) -> 3
A11: =IF(W0_Scope!A31="","",W0_Scope!A31) -> F-03 | B11: =IF($A11="","",W0_Scope!B31) -> Discovery, Reading History & Recommendation | C11: =IF($A11="","",SUMIF(W1_FunctionList!$A$10:$A$87,$A11,W1_FunctionList!$Q$10:$Q$87)) -> 15 | D11: =IF($A11="","",COUNTIF(W2_Costing!$B$9:$B$128,$A11)) -> #REF! | E11: =IF($A11="","",SUMIF(W2_Costing!$B$9:$B$128,$A11,W2_Costing!$E$9:$E$128)) -> #N/A | F11: =IF($A11="","",SUMIFS(W2_Costing!$J$9:$J$128,W2_Costing!$B$9:$B$128,$A11,W2_Costing!$N$9:$N$128,"Must")) -> #N/A | G11: =IF($A11="","",SUMIFS(W2_Costing!$J$9:$J$128,W2_Costing!$B$9:$B$128,$A11,W2_Costing!$N$9:$N$128,"Should")) -> #N/A | H11: =IF($A11="","",SUMIFS(W2_Costing!$J$9:$J$128,W2_Costing!$B$9:$B$128,$A11,W2_Costing!$N$9:$N$128,"Could")) -> #N/A | I11: =IF($A11="","",SUMIFS(W2_Costing!$J$9:$J$128,W2_Costing!$B$9:$B$128,$A11,W2_Costing!$N$9:$N$128,"Won't")) -> #N/A | J11: =IF($A11="","",F11+G11+H11) -> #N/A | K11: =IF($A11="","",SUMIFS(W2_Costing!$M$9:$M$128,W2_Costing!$B$9:$B$128,$A11)-SUMIFS(W2_Costing!$M$9:$M$128,W2_Costing!$B$9:$B$128,$A11,W2_Costing!$N$9:$N$128,"Won't")) -> #N/A | L11: =IF($A11="","",IF(J11=0,0,F11/J11)) -> #N/A | M11: =IF($A11="","",SUMIF(W1_FunctionList!$A$10:$A$87,$A11,W1_FunctionList!$N$10:$N$87)) -> 176 | N11: =IF($A11="","",SUMIF(W1_FunctionList!$A$10:$A$87,$A11,W1_FunctionList!$S$10:$S$87)) -> 46 | O11: =IF(OR($A11="",N11=0),"",M11/N11) -> 3.826087
A12: =IF(W0_Scope!A32="","",W0_Scope!A32) -> F-04 | B12: =IF($A12="","",W0_Scope!B32) -> Platform, Access & Operations | C12: =IF($A12="","",SUMIF(W1_FunctionList!$A$10:$A$87,$A12,W1_FunctionList!$Q$10:$Q$87)) -> 15 | D12: =IF($A12="","",COUNTIF(W2_Costing!$B$9:$B$128,$A12)) -> #REF! | E12: =IF($A12="","",SUMIF(W2_Costing!$B$9:$B$128,$A12,W2_Costing!$E$9:$E$128)) -> #N/A | F12: =IF($A12="","",SUMIFS(W2_Costing!$J$9:$J$128,W2_Costing!$B$9:$B$128,$A12,W2_Costing!$N$9:$N$128,"Must")) -> #N/A | G12: =IF($A12="","",SUMIFS(W2_Costing!$J$9:$J$128,W2_Costing!$B$9:$B$128,$A12,W2_Costing!$N$9:$N$128,"Should")) -> #N/A | H12: =IF($A12="","",SUMIFS(W2_Costing!$J$9:$J$128,W2_Costing!$B$9:$B$128,$A12,W2_Costing!$N$9:$N$128,"Could")) -> #N/A | I12: =IF($A12="","",SUMIFS(W2_Costing!$J$9:$J$128,W2_Costing!$B$9:$B$128,$A12,W2_Costing!$N$9:$N$128,"Won't")) -> #N/A | J12: =IF($A12="","",F12+G12+H12) -> #N/A | K12: =IF($A12="","",SUMIFS(W2_Costing!$M$9:$M$128,W2_Costing!$B$9:$B$128,$A12)-SUMIFS(W2_Costing!$M$9:$M$128,W2_Costing!$B$9:$B$128,$A12,W2_Costing!$N$9:$N$128,"Won't")) -> #N/A | L12: =IF($A12="","",IF(J12=0,0,F12/J12)) -> #N/A | M12: =IF($A12="","",SUMIF(W1_FunctionList!$A$10:$A$87,$A12,W1_FunctionList!$N$10:$N$87)) -> 196 | N12: =IF($A12="","",SUMIF(W1_FunctionList!$A$10:$A$87,$A12,W1_FunctionList!$S$10:$S$87)) -> 20 | O12: =IF(OR($A12="",N12=0),"",M12/N12) -> 9.8
A13: =IF(W0_Scope!A33="","",W0_Scope!A33) | B13: =IF($A13="","",W0_Scope!B33) | C13: =IF($A13="","",SUMIF(W1_FunctionList!$A$10:$A$87,$A13,W1_FunctionList!$Q$10:$Q$87)) | D13: =IF($A13="","",COUNTIF(W2_Costing!$B$9:$B$128,$A13)) | E13: =IF($A13="","",SUMIF(W2_Costing!$B$9:$B$128,$A13,W2_Costing!$E$9:$E$128)) | F13: =IF($A13="","",SUMIFS(W2_Costing!$J$9:$J$128,W2_Costing!$B$9:$B$128,$A13,W2_Costing!$N$9:$N$128,"Must")) | G13: =IF($A13="","",SUMIFS(W2_Costing!$J$9:$J$128,W2_Costing!$B$9:$B$128,$A13,W2_Costing!$N$9:$N$128,"Should")) | H13: =IF($A13="","",SUMIFS(W2_Costing!$J$9:$J$128,W2_Costing!$B$9:$B$128,$A13,W2_Costing!$N$9:$N$128,"Could")) | I13: =IF($A13="","",SUMIFS(W2_Costing!$J$9:$J$128,W2_Costing!$B$9:$B$128,$A13,W2_Costing!$N$9:$N$128,"Won't")) | J13: =IF($A13="","",F13+G13+H13) | K13: =IF($A13="","",SUMIFS(W2_Costing!$M$9:$M$128,W2_Costing!$B$9:$B$128,$A13)-SUMIFS(W2_Costing!$M$9:$M$128,W2_Costing!$B$9:$B$128,$A13,W2_Costing!$N$9:$N$128,"Won't")) | L13: =IF($A13="","",IF(J13=0,0,F13/J13)) | M13: =IF($A13="","",SUMIF(W1_FunctionList!$A$10:$A$87,$A13,W1_FunctionList!$N$10:$N$87)) | N13: =IF($A13="","",SUMIF(W1_FunctionList!$A$10:$A$87,$A13,W1_FunctionList!$S$10:$S$87)) | O13: =IF(OR($A13="",N13=0),"",M13/N13)
A14: =IF(W0_Scope!A34="","",W0_Scope!A34) | B14: =IF($A14="","",W0_Scope!B34) | C14: =IF($A14="","",SUMIF(W1_FunctionList!$A$10:$A$87,$A14,W1_FunctionList!$Q$10:$Q$87)) | D14: =IF($A14="","",COUNTIF(W2_Costing!$B$9:$B$128,$A14)) | E14: =IF($A14="","",SUMIF(W2_Costing!$B$9:$B$128,$A14,W2_Costing!$E$9:$E$128)) | F14: =IF($A14="","",SUMIFS(W2_Costing!$J$9:$J$128,W2_Costing!$B$9:$B$128,$A14,W2_Costing!$N$9:$N$128,"Must")) | G14: =IF($A14="","",SUMIFS(W2_Costing!$J$9:$J$128,W2_Costing!$B$9:$B$128,$A14,W2_Costing!$N$9:$N$128,"Should")) | H14: =IF($A14="","",SUMIFS(W2_Costing!$J$9:$J$128,W2_Costing!$B$9:$B$128,$A14,W2_Costing!$N$9:$N$128,"Could")) | I14: =IF($A14="","",SUMIFS(W2_Costing!$J$9:$J$128,W2_Costing!$B$9:$B$128,$A14,W2_Costing!$N$9:$N$128,"Won't")) | J14: =IF($A14="","",F14+G14+H14) | K14: =IF($A14="","",SUMIFS(W2_Costing!$M$9:$M$128,W2_Costing!$B$9:$B$128,$A14)-SUMIFS(W2_Costing!$M$9:$M$128,W2_Costing!$B$9:$B$128,$A14,W2_Costing!$N$9:$N$128,"Won't")) | L14: =IF($A14="","",IF(J14=0,0,F14/J14)) | M14: =IF($A14="","",SUMIF(W1_FunctionList!$A$10:$A$87,$A14,W1_FunctionList!$N$10:$N$87)) | N14: =IF($A14="","",SUMIF(W1_FunctionList!$A$10:$A$87,$A14,W1_FunctionList!$S$10:$S$87)) | O14: =IF(OR($A14="",N14=0),"",M14/N14)
A15: =IF(W0_Scope!A35="","",W0_Scope!A35) | B15: =IF($A15="","",W0_Scope!B35) | C15: =IF($A15="","",SUMIF(W1_FunctionList!$A$10:$A$87,$A15,W1_FunctionList!$Q$10:$Q$87)) | D15: =IF($A15="","",COUNTIF(W2_Costing!$B$9:$B$128,$A15)) | E15: =IF($A15="","",SUMIF(W2_Costing!$B$9:$B$128,$A15,W2_Costing!$E$9:$E$128)) | F15: =IF($A15="","",SUMIFS(W2_Costing!$J$9:$J$128,W2_Costing!$B$9:$B$128,$A15,W2_Costing!$N$9:$N$128,"Must")) | G15: =IF($A15="","",SUMIFS(W2_Costing!$J$9:$J$128,W2_Costing!$B$9:$B$128,$A15,W2_Costing!$N$9:$N$128,"Should")) | H15: =IF($A15="","",SUMIFS(W2_Costing!$J$9:$J$128,W2_Costing!$B$9:$B$128,$A15,W2_Costing!$N$9:$N$128,"Could")) | I15: =IF($A15="","",SUMIFS(W2_Costing!$J$9:$J$128,W2_Costing!$B$9:$B$128,$A15,W2_Costing!$N$9:$N$128,"Won't")) | J15: =IF($A15="","",F15+G15+H15) | K15: =IF($A15="","",SUMIFS(W2_Costing!$M$9:$M$128,W2_Costing!$B$9:$B$128,$A15)-SUMIFS(W2_Costing!$M$9:$M$128,W2_Costing!$B$9:$B$128,$A15,W2_Costing!$N$9:$N$128,"Won't")) | L15: =IF($A15="","",IF(J15=0,0,F15/J15)) | M15: =IF($A15="","",SUMIF(W1_FunctionList!$A$10:$A$87,$A15,W1_FunctionList!$N$10:$N$87)) | N15: =IF($A15="","",SUMIF(W1_FunctionList!$A$10:$A$87,$A15,W1_FunctionList!$S$10:$S$87)) | O15: =IF(OR($A15="",N15=0),"",M15/N15)
A16: =IF(W0_Scope!A36="","",W0_Scope!A36) | B16: =IF($A16="","",W0_Scope!B36) | C16: =IF($A16="","",SUMIF(W1_FunctionList!$A$10:$A$87,$A16,W1_FunctionList!$Q$10:$Q$87)) | D16: =IF($A16="","",COUNTIF(W2_Costing!$B$9:$B$128,$A16)) | E16: =IF($A16="","",SUMIF(W2_Costing!$B$9:$B$128,$A16,W2_Costing!$E$9:$E$128)) | F16: =IF($A16="","",SUMIFS(W2_Costing!$J$9:$J$128,W2_Costing!$B$9:$B$128,$A16,W2_Costing!$N$9:$N$128,"Must")) | G16: =IF($A16="","",SUMIFS(W2_Costing!$J$9:$J$128,W2_Costing!$B$9:$B$128,$A16,W2_Costing!$N$9:$N$128,"Should")) | H16: =IF($A16="","",SUMIFS(W2_Costing!$J$9:$J$128,W2_Costing!$B$9:$B$128,$A16,W2_Costing!$N$9:$N$128,"Could")) | I16: =IF($A16="","",SUMIFS(W2_Costing!$J$9:$J$128,W2_Costing!$B$9:$B$128,$A16,W2_Costing!$N$9:$N$128,"Won't")) | J16: =IF($A16="","",F16+G16+H16) | K16: =IF($A16="","",SUMIFS(W2_Costing!$M$9:$M$128,W2_Costing!$B$9:$B$128,$A16)-SUMIFS(W2_Costing!$M$9:$M$128,W2_Costing!$B$9:$B$128,$A16,W2_Costing!$N$9:$N$128,"Won't")) | L16: =IF($A16="","",IF(J16=0,0,F16/J16)) | M16: =IF($A16="","",SUMIF(W1_FunctionList!$A$10:$A$87,$A16,W1_FunctionList!$N$10:$N$87)) | N16: =IF($A16="","",SUMIF(W1_FunctionList!$A$10:$A$87,$A16,W1_FunctionList!$S$10:$S$87)) | O16: =IF(OR($A16="",N16=0),"",M16/N16)
A17: =IF(W0_Scope!A37="","",W0_Scope!A37) | B17: =IF($A17="","",W0_Scope!B37) | C17: =IF($A17="","",SUMIF(W1_FunctionList!$A$10:$A$87,$A17,W1_FunctionList!$Q$10:$Q$87)) | D17: =IF($A17="","",COUNTIF(W2_Costing!$B$9:$B$128,$A17)) | E17: =IF($A17="","",SUMIF(W2_Costing!$B$9:$B$128,$A17,W2_Costing!$E$9:$E$128)) | F17: =IF($A17="","",SUMIFS(W2_Costing!$J$9:$J$128,W2_Costing!$B$9:$B$128,$A17,W2_Costing!$N$9:$N$128,"Must")) | G17: =IF($A17="","",SUMIFS(W2_Costing!$J$9:$J$128,W2_Costing!$B$9:$B$128,$A17,W2_Costing!$N$9:$N$128,"Should")) | H17: =IF($A17="","",SUMIFS(W2_Costing!$J$9:$J$128,W2_Costing!$B$9:$B$128,$A17,W2_Costing!$N$9:$N$128,"Could")) | I17: =IF($A17="","",SUMIFS(W2_Costing!$J$9:$J$128,W2_Costing!$B$9:$B$128,$A17,W2_Costing!$N$9:$N$128,"Won't")) | J17: =IF($A17="","",F17+G17+H17) | K17: =IF($A17="","",SUMIFS(W2_Costing!$M$9:$M$128,W2_Costing!$B$9:$B$128,$A17)-SUMIFS(W2_Costing!$M$9:$M$128,W2_Costing!$B$9:$B$128,$A17,W2_Costing!$N$9:$N$128,"Won't")) | L17: =IF($A17="","",IF(J17=0,0,F17/J17)) | M17: =IF($A17="","",SUMIF(W1_FunctionList!$A$10:$A$87,$A17,W1_FunctionList!$N$10:$N$87)) | N17: =IF($A17="","",SUMIF(W1_FunctionList!$A$10:$A$87,$A17,W1_FunctionList!$S$10:$S$87)) | O17: =IF(OR($A17="",N17=0),"",M17/N17)
A18: =IF(W0_Scope!A38="","",W0_Scope!A38) | B18: =IF($A18="","",W0_Scope!B38) | C18: =IF($A18="","",SUMIF(W1_FunctionList!$A$10:$A$87,$A18,W1_FunctionList!$Q$10:$Q$87)) | D18: =IF($A18="","",COUNTIF(W2_Costing!$B$9:$B$128,$A18)) | E18: =IF($A18="","",SUMIF(W2_Costing!$B$9:$B$128,$A18,W2_Costing!$E$9:$E$128)) | F18: =IF($A18="","",SUMIFS(W2_Costing!$J$9:$J$128,W2_Costing!$B$9:$B$128,$A18,W2_Costing!$N$9:$N$128,"Must")) | G18: =IF($A18="","",SUMIFS(W2_Costing!$J$9:$J$128,W2_Costing!$B$9:$B$128,$A18,W2_Costing!$N$9:$N$128,"Should")) | H18: =IF($A18="","",SUMIFS(W2_Costing!$J$9:$J$128,W2_Costing!$B$9:$B$128,$A18,W2_Costing!$N$9:$N$128,"Could")) | I18: =IF($A18="","",SUMIFS(W2_Costing!$J$9:$J$128,W2_Costing!$B$9:$B$128,$A18,W2_Costing!$N$9:$N$128,"Won't")) | J18: =IF($A18="","",F18+G18+H18) | K18: =IF($A18="","",SUMIFS(W2_Costing!$M$9:$M$128,W2_Costing!$B$9:$B$128,$A18)-SUMIFS(W2_Costing!$M$9:$M$128,W2_Costing!$B$9:$B$128,$A18,W2_Costing!$N$9:$N$128,"Won't")) | L18: =IF($A18="","",IF(J18=0,0,F18/J18)) | M18: =IF($A18="","",SUMIF(W1_FunctionList!$A$10:$A$87,$A18,W1_FunctionList!$N$10:$N$87)) | N18: =IF($A18="","",SUMIF(W1_FunctionList!$A$10:$A$87,$A18,W1_FunctionList!$S$10:$S$87)) | O18: =IF(OR($A18="",N18=0),"",M18/N18)
A19: =IF(W0_Scope!A39="","",W0_Scope!A39) | B19: =IF($A19="","",W0_Scope!B39) | C19: =IF($A19="","",SUMIF(W1_FunctionList!$A$10:$A$87,$A19,W1_FunctionList!$Q$10:$Q$87)) | D19: =IF($A19="","",COUNTIF(W2_Costing!$B$9:$B$128,$A19)) | E19: =IF($A19="","",SUMIF(W2_Costing!$B$9:$B$128,$A19,W2_Costing!$E$9:$E$128)) | F19: =IF($A19="","",SUMIFS(W2_Costing!$J$9:$J$128,W2_Costing!$B$9:$B$128,$A19,W2_Costing!$N$9:$N$128,"Must")) | G19: =IF($A19="","",SUMIFS(W2_Costing!$J$9:$J$128,W2_Costing!$B$9:$B$128,$A19,W2_Costing!$N$9:$N$128,"Should")) | H19: =IF($A19="","",SUMIFS(W2_Costing!$J$9:$J$128,W2_Costing!$B$9:$B$128,$A19,W2_Costing!$N$9:$N$128,"Could")) | I19: =IF($A19="","",SUMIFS(W2_Costing!$J$9:$J$128,W2_Costing!$B$9:$B$128,$A19,W2_Costing!$N$9:$N$128,"Won't")) | J19: =IF($A19="","",F19+G19+H19) | K19: =IF($A19="","",SUMIFS(W2_Costing!$M$9:$M$128,W2_Costing!$B$9:$B$128,$A19)-SUMIFS(W2_Costing!$M$9:$M$128,W2_Costing!$B$9:$B$128,$A19,W2_Costing!$N$9:$N$128,"Won't")) | L19: =IF($A19="","",IF(J19=0,0,F19/J19)) | M19: =IF($A19="","",SUMIF(W1_FunctionList!$A$10:$A$87,$A19,W1_FunctionList!$N$10:$N$87)) | N19: =IF($A19="","",SUMIF(W1_FunctionList!$A$10:$A$87,$A19,W1_FunctionList!$S$10:$S$87)) | O19: =IF(OR($A19="",N19=0),"",M19/N19)
A20: =IF(W0_Scope!A40="","",W0_Scope!A40) | B20: =IF($A20="","",W0_Scope!B40) | C20: =IF($A20="","",SUMIF(W1_FunctionList!$A$10:$A$87,$A20,W1_FunctionList!$Q$10:$Q$87)) | D20: =IF($A20="","",COUNTIF(W2_Costing!$B$9:$B$128,$A20)) | E20: =IF($A20="","",SUMIF(W2_Costing!$B$9:$B$128,$A20,W2_Costing!$E$9:$E$128)) | F20: =IF($A20="","",SUMIFS(W2_Costing!$J$9:$J$128,W2_Costing!$B$9:$B$128,$A20,W2_Costing!$N$9:$N$128,"Must")) | G20: =IF($A20="","",SUMIFS(W2_Costing!$J$9:$J$128,W2_Costing!$B$9:$B$128,$A20,W2_Costing!$N$9:$N$128,"Should")) | H20: =IF($A20="","",SUMIFS(W2_Costing!$J$9:$J$128,W2_Costing!$B$9:$B$128,$A20,W2_Costing!$N$9:$N$128,"Could")) | I20: =IF($A20="","",SUMIFS(W2_Costing!$J$9:$J$128,W2_Costing!$B$9:$B$128,$A20,W2_Costing!$N$9:$N$128,"Won't")) | J20: =IF($A20="","",F20+G20+H20) | K20: =IF($A20="","",SUMIFS(W2_Costing!$M$9:$M$128,W2_Costing!$B$9:$B$128,$A20)-SUMIFS(W2_Costing!$M$9:$M$128,W2_Costing!$B$9:$B$128,$A20,W2_Costing!$N$9:$N$128,"Won't")) | L20: =IF($A20="","",IF(J20=0,0,F20/J20)) | M20: =IF($A20="","",SUMIF(W1_FunctionList!$A$10:$A$87,$A20,W1_FunctionList!$N$10:$N$87)) | N20: =IF($A20="","",SUMIF(W1_FunctionList!$A$10:$A$87,$A20,W1_FunctionList!$S$10:$S$87)) | O20: =IF(OR($A20="",N20=0),"",M20/N20)
B21: PROJECT TOTAL | C21: =SUM(C9:C20) -> 45 | D21: =SUM(D9:D20) -> #REF! | E21: =SUM(E9:E20) -> #N/A | F21: =SUM(F9:F20) -> #N/A | G21: =SUM(G9:G20) -> #N/A | H21: =SUM(H9:H20) -> #N/A | I21: =SUM(I9:I20) -> #N/A | J21: =SUM(J9:J20) -> #N/A | K21: =SUM(K9:K20) -> #N/A | L21: =IF(J21=0,0,F21/J21) -> #N/A | M21: =SUM(M9:M20) -> 532 | N21: =SUM(N9:N20) -> 110 | O21: =IF(N21=0,"",M21/N21) -> 4.8363636
A22: Columns M-O compare the two sizing methods FEATURE BY FEATURE. Data functions (ILF / EIF) are counted once for the whole product, so column N holds transactional function points only — read column O as a RELATIVE figure. Features should cluster around a similar hours-per-FP ratio; the one sitting far from its siblings is where somebody mis-sized something, or where NC rows are carrying work that function points cannot see.
A24: The three headline figures — always say which one you mean
A25: Scenario | B25: Scope | C25: Person-hours | D25: Cost (VND) | E25: Meaning
A26: Committed | B26: Must only | C26: =F21 -> #N/A | D26: =SUMIFS(W2_Costing!$M$9:$M$128,W2_Costing!$N$9:$N$128,"Must") -> #N/A | E26: What the team guarantees to deliver — the Minimum Usable SubseT
A27: Expected | B27: Must + Should | C27: =F21+G21 -> #N/A | D27: =SUMIFS(W2_Costing!$M$9:$M$128,W2_Costing!$N$9:$N$128,"Must")+SUMIFS(W2_Costing!$M$9:$M$128,W2_Costing!$N$9:$N$128,"Should") -> #N/A | E27: The figure given to the client; the base cash flow for Session 8
A28: Ceiling | B28: Must + Should + Could | C28: =J21 -> #N/A | D28: =K21 -> #N/A | E28: If the Could contingency pool is never consumed
A30: Threshold check — as first written (W1) vs after the W4 decisions
A31: Indicator | B31: As written | C31: After W4 | D31: Threshold | E31: Verdict (after W4)
A32: Must share of in-scope effort | B32: =IFERROR(SUMIFS(W2_Costing!$J$9:$J$128,W1_FunctionList!$H$10:$H$87,"Must")/(SUMIFS(W2_Costing!$J$9:$J$128,W1_FunctionList!$H$10:$H$87,"Must")+SUMIFS(W2_Costing!$J$9:$J$128,W1_FunctionList!$H$10:$H$87,"Should")+SUMIFS(W2_Costing!$J$9:$J$128,W1_FunctionList!$H$10:$H$87,"Could")),0) -> 0 | C32: =IF(J21=0,0,F21/J21) -> #N/A | D32: =Parameters!$B$48 -> 0.6 | E32: =IF(C32<=D32,"PASS","ABOVE CEILING - demote some Must rows") -> #N/A
A33: Could share (contingency pool) | B33: =IFERROR(SUMIFS(W2_Costing!$J$9:$J$128,W1_FunctionList!$H$10:$H$87,"Could")/(SUMIFS(W2_Costing!$J$9:$J$128,W1_FunctionList!$H$10:$H$87,"Must")+SUMIFS(W2_Costing!$J$9:$J$128,W1_FunctionList!$H$10:$H$87,"Should")+SUMIFS(W2_Costing!$J$9:$J$128,W1_FunctionList!$H$10:$H$87,"Could")),0) -> 0 | C33: =IF(J21=0,0,H21/J21) -> #N/A | D33: =Parameters!$B$49 -> 0.2 | E33: =IF(C33>=D33*0.75,"PASS","POOL TOO THIN - nothing left to drop when late") -> #N/A
A34: In-scope effort vs team capacity (p-h) | B34: =(SUMIFS(W2_Costing!$J$9:$J$128,W1_FunctionList!$H$10:$H$87,"Must")+SUMIFS(W2_Costing!$J$9:$J$128,W1_FunctionList!$H$10:$H$87,"Should")+SUMIFS(W2_Costing!$J$9:$J$128,W1_FunctionList!$H$10:$H$87,"Could")) -> #N/A | C34: =J21 -> #N/A | D34: =Parameters!$B$45 -> 360 | E34: =IF(C34<=D34,"PASS","OVER CAPACITY") -> #N/A
A35: Hidden technical work, share of effort | B35: =IFERROR(SUMIFS(W2_Costing!$J$9:$J$128,W1_FunctionList!$P$10:$P$87,"Yes")/SUM(W2_Costing!$J$9:$J$128),0) -> 0 | C35: =IFERROR(SUMIFS(W2_Costing!$J$9:$J$128,W1_FunctionList!$P$10:$P$87,"Yes")/SUM(W2_Costing!$J$9:$J$128),0) -> 0 | D35: =Parameters!$B$50 -> 0.1 | E35: =IF(C35>=D35,"PASS","MISSING - revisit access control, deployment, tests") -> MISSING - revisit access control, deployment, tests
A36: L3 rows above the hour ceiling | B36: =COUNTIF(W1_FunctionList!$N$10:$N$87,">"&Parameters!$B$51) -> 0 | C36: =COUNTIF(W1_FunctionList!$N$10:$N$87,">"&Parameters!$B$51) -> 0 | D36: 0 | E36: =IF(C36=0,"PASS","SPLIT FURTHER: "&C36&" rows") -> PASS
A37: Feature count | B37: =W0_Scope!$B$41 -> 4 | C37: =W0_Scope!$B$41 -> 4 | D37: =Parameters!$B$52&"-"&Parameters!$B$53 -> 3-6 | E37: =IF(AND(C37>=Parameters!$B$52,C37<=Parameters!$B$53),"PASS","REVIEW the feature split") -> PASS
A39: Three observations the team carries into W4:

Sheet W4_Prioritization
A1: W4 — Repair and prioritise
A3: INPUT | B3: Initial priority from W1, the defect log from W3, and the team capacity from Parameters.
A4: OUTPUT | B4: An effective priority for every L2 function, each change carrying the rule it followed and a written justification. The effective priority flows back into W2_Costing and re-drives every total.
A5: PROCEDURE | B5: 1. Sort every W3 defect into one of three buckets: Fix now / Clarify / Reject. Rejecting is allowed, but the reason must be written down. 2. Repair STRUCTURE first: merge duplicates, add clock-triggered functions, add missing hidden work, split rows above the ceiling. 3. Recalculate and read the new numbers. 4. CUT: first move rows out to Won't-have, then demote Must -> Should -> Could. One sentence of justification per change. 5. Recalculate and confirm every threshold passes.
A6: THE RULE ON THE BOARD | B6: Cut by lowering priority, NEVER by lowering effort. Effort changes only when the technical scope of the row genuinely changes, and what was dropped must be written down.
A9: Decision rules — every priority change must name the rule it followed
A10: Rule | B10: MoSCoW meaning | C10: Test question | E10: Kano category that usually maps here
A11: R1 · Must | B11: The release has no viable use without it | C11: If it is absent on delivery day, is the release unusable? | E11: Must-be — invisible when present, fatal when absent
A12: R2 · Should | B12: Important, but a workaround exists | C12: Painful to leave out, yet the solution still works? | E12: One-dimensional — more of it, more satisfaction
A13: R3 · Could | B13: Desirable, low impact if dropped | C13: Would anyone notice within the first month? | E13: Attractive — a delighter, never a Must
A14: R4 · Won't | B14: Agreed as out of scope for this release | C14: Did the client accept deferring it, and is it in W0 Table 3? | E14: Indifferent — asked for, but nobody actually cares
A18: Feature | B18: L2 ID | C18: L2 function name | D18: Initial priority | E18: Rule applied | F18: Kano category | G18: New priority | H18: Effective priority | I18: Justification (required if changed) | J18: Person-hours | K18: Cost (VND)
A19: {=IF($B19="","",IFERROR(INDEX(W1_FunctionList!$A$10:$A$87,MATCH($B19,W1_FunctionList!$B$10:$B$87,0)),""))} -> F-01 | B19: {=IFERROR(INDEX(W1_FunctionList!$B$10:$B$87,MATCH(1,W1_FunctionList!$R$10:$R$87,0)),"")} -> FR-01-01 | C19: {=IF($B19="","",IFERROR(INDEX(W1_FunctionList!$C$10:$C$87,MATCH($B19,W1_FunctionList!$B$10:$B$87,0)),""))} -> View book shelf location | D19: {=IF($B19="","",IFERROR(INDEX(W1_FunctionList!$H$10:$H$87,MATCH($B19,W1_FunctionList!$B$10:$B$87,0)),""))} -> Must | H19: =IF($B19="","",IF(G19="",D19,G19)) -> Must | J19: =IF($B19="","",SUMIF(W2_Costing!$C$9:$C$128,$B19,W2_Costing!$J$9:$J$128)) -> #N/A | K19: =IF($B19="","",SUMIF(W2_Costing!$C$9:$C$128,$B19,W2_Costing!$M$9:$M$128)) -> #N/A
A20: {=IF($B20="","",IFERROR(INDEX(W1_FunctionList!$A$10:$A$87,MATCH($B20,W1_FunctionList!$B$10:$B$87,0)),""))} -> F-01 | B20: {=IFERROR(INDEX(W1_FunctionList!$B$10:$B$87,MATCH(2,W1_FunctionList!$R$10:$R$87,0)),"")} -> FR-01-02 | C20: {=IF($B20="","",IFERROR(INDEX(W1_FunctionList!$C$10:$C$87,MATCH($B20,W1_FunctionList!$B$10:$B$87,0)),""))} -> Browse the digital library map | D20: {=IF($B20="","",IFERROR(INDEX(W1_FunctionList!$H$10:$H$87,MATCH($B20,W1_FunctionList!$B$10:$B$87,0)),""))} -> Must | H20: =IF($B20="","",IF(G20="",D20,G20)) -> Must | J20: =IF($B20="","",SUMIF(W2_Costing!$C$9:$C$128,$B20,W2_Costing!$J$9:$J$128)) -> #N/A | K20: =IF($B20="","",SUMIF(W2_Costing!$C$9:$C$128,$B20,W2_Costing!$M$9:$M$128)) -> #N/A
A21: {=IF($B21="","",IFERROR(INDEX(W1_FunctionList!$A$10:$A$87,MATCH($B21,W1_FunctionList!$B$10:$B$87,0)),""))} -> F-01 | B21: {=IFERROR(INDEX(W1_FunctionList!$B$10:$B$87,MATCH(3,W1_FunctionList!$R$10:$R$87,0)),"")} -> FR-01-03 | C21: {=IF($B21="","",IFERROR(INDEX(W1_FunctionList!$C$10:$C$87,MATCH($B21,W1_FunctionList!$B$10:$B$87,0)),""))} -> Show a book's room on the map | D21: {=IF($B21="","",IFERROR(INDEX(W1_FunctionList!$H$10:$H$87,MATCH($B21,W1_FunctionList!$B$10:$B$87,0)),""))} -> Should | E21: R3 Could | F21: Attractive | G21: Could | H21: =IF($B21="","",IF(G21="",D21,G21)) -> Could | I21: Workaround exists: readers still see floor, room and shelf code (FR-01-01) and can browse the map (FR-01-02); the deep link from a book to its highlighted room is a convenience. Nobody would miss it in the first month. | J21: =IF($B21="","",SUMIF(W2_Costing!$C$9:$C$128,$B21,W2_Costing!$J$9:$J$128)) -> #N/A | K21: =IF($B21="","",SUMIF(W2_Costing!$C$9:$C$128,$B21,W2_Costing!$M$9:$M$128)) -> #N/A
A22: {=IF($B22="","",IFERROR(INDEX(W1_FunctionList!$A$10:$A$87,MATCH($B22,W1_FunctionList!$B$10:$B$87,0)),""))} -> F-01 | B22: {=IFERROR(INDEX(W1_FunctionList!$B$10:$B$87,MATCH(4,W1_FunctionList!$R$10:$R$87,0)),"")} -> FR-01-04 | C22: {=IF($B22="","",IFERROR(INDEX(W1_FunctionList!$C$10:$C$87,MATCH($B22,W1_FunctionList!$B$10:$B$87,0)),""))} -> Prepare the digital floor plan | D22: {=IF($B22="","",IFERROR(INDEX(W1_FunctionList!$H$10:$H$87,MATCH($B22,W1_FunctionList!$B$10:$B$87,0)),""))} -> Must | H22: =IF($B22="","",IF(G22="",D22,G22)) -> Must | J22: =IF($B22="","",SUMIF(W2_Costing!$C$9:$C$128,$B22,W2_Costing!$J$9:$J$128)) -> #N/A | K22: =IF($B22="","",SUMIF(W2_Costing!$C$9:$C$128,$B22,W2_Costing!$M$9:$M$128)) -> #N/A
A23: {=IF($B23="","",IFERROR(INDEX(W1_FunctionList!$A$10:$A$87,MATCH($B23,W1_FunctionList!$B$10:$B$87,0)),""))} -> F-01 | B23: {=IFERROR(INDEX(W1_FunctionList!$B$10:$B$87,MATCH(5,W1_FunctionList!$R$10:$R$87,0)),"")} -> FR-01-05 | C23: {=IF($B23="","",IFERROR(INDEX(W1_FunctionList!$C$10:$C$87,MATCH($B23,W1_FunctionList!$B$10:$B$87,0)),""))} -> Check room codes against the internal system | D23: {=IF($B23="","",IFERROR(INDEX(W1_FunctionList!$H$10:$H$87,MATCH($B23,W1_FunctionList!$B$10:$B$87,0)),""))} -> Should | H23: =IF($B23="","",IF(G23="",D23,G23)) -> Should | J23: =IF($B23="","",SUMIF(W2_Costing!$C$9:$C$128,$B23,W2_Costing!$J$9:$J$128)) -> #N/A | K23: =IF($B23="","",SUMIF(W2_Costing!$C$9:$C$128,$B23,W2_Costing!$M$9:$M$128)) -> #N/A
A24: {=IF($B24="","",IFERROR(INDEX(W1_FunctionList!$A$10:$A$87,MATCH($B24,W1_FunctionList!$B$10:$B$87,0)),""))} -> F-02 | B24: {=IFERROR(INDEX(W1_FunctionList!$B$10:$B$87,MATCH(6,W1_FunctionList!$R$10:$R$87,0)),"")} -> FR-02-01 | C24: {=IF($B24="","",IFERROR(INDEX(W1_FunctionList!$C$10:$C$87,MATCH($B24,W1_FunctionList!$B$10:$B$87,0)),""))} -> Write a book review | D24: {=IF($B24="","",IFERROR(INDEX(W1_FunctionList!$H$10:$H$87,MATCH($B24,W1_FunctionList!$B$10:$B$87,0)),""))} -> Must | H24: =IF($B24="","",IF(G24="",D24,G24)) -> Must | J24: =IF($B24="","",SUMIF(W2_Costing!$C$9:$C$128,$B24,W2_Costing!$J$9:$J$128)) -> #N/A | K24: =IF($B24="","",SUMIF(W2_Costing!$C$9:$C$128,$B24,W2_Costing!$M$9:$M$128)) -> #N/A
A25: {=IF($B25="","",IFERROR(INDEX(W1_FunctionList!$A$10:$A$87,MATCH($B25,W1_FunctionList!$B$10:$B$87,0)),""))} -> F-02 | B25: {=IFERROR(INDEX(W1_FunctionList!$B$10:$B$87,MATCH(7,W1_FunctionList!$R$10:$R$87,0)),"")} -> FR-02-02 | C25: {=IF($B25="","",IFERROR(INDEX(W1_FunctionList!$C$10:$C$87,MATCH($B25,W1_FunctionList!$B$10:$B$87,0)),""))} -> View book reviews | D25: {=IF($B25="","",IFERROR(INDEX(W1_FunctionList!$H$10:$H$87,MATCH($B25,W1_FunctionList!$B$10:$B$87,0)),""))} -> Must | H25: =IF($B25="","",IF(G25="",D25,G25)) -> Must | J25: =IF($B25="","",SUMIF(W2_Costing!$C$9:$C$128,$B25,W2_Costing!$J$9:$J$128)) -> #N/A | K25: =IF($B25="","",SUMIF(W2_Costing!$C$9:$C$128,$B25,W2_Costing!$M$9:$M$128)) -> #N/A
A26: {=IF($B26="","",IFERROR(INDEX(W1_FunctionList!$A$10:$A$87,MATCH($B26,W1_FunctionList!$B$10:$B$87,0)),""))} -> F-02 | B26: {=IFERROR(INDEX(W1_FunctionList!$B$10:$B$87,MATCH(8,W1_FunctionList!$R$10:$R$87,0)),"")} -> FR-02-03 | C26: {=IF($B26="","",IFERROR(INDEX(W1_FunctionList!$C$10:$C$87,MATCH($B26,W1_FunctionList!$B$10:$B$87,0)),""))} -> Edit own review | D26: {=IF($B26="","",IFERROR(INDEX(W1_FunctionList!$H$10:$H$87,MATCH($B26,W1_FunctionList!$B$10:$B$87,0)),""))} -> Could | H26: =IF($B26="","",IF(G26="",D26,G26)) -> Could | J26: =IF($B26="","",SUMIF(W2_Costing!$C$9:$C$128,$B26,W2_Costing!$J$9:$J$128)) -> #N/A | K26: =IF($B26="","",SUMIF(W2_Costing!$C$9:$C$128,$B26,W2_Costing!$M$9:$M$128)) -> #N/A
A27: {=IF($B27="","",IFERROR(INDEX(W1_FunctionList!$A$10:$A$87,MATCH($B27,W1_FunctionList!$B$10:$B$87,0)),""))} -> F-02 | B27: {=IFERROR(INDEX(W1_FunctionList!$B$10:$B$87,MATCH(9,W1_FunctionList!$R$10:$R$87,0)),"")} -> FR-02-04 | C27: {=IF($B27="","",IFERROR(INDEX(W1_FunctionList!$C$10:$C$87,MATCH($B27,W1_FunctionList!$B$10:$B$87,0)),""))} -> Delete own review | D27: {=IF($B27="","",IFERROR(INDEX(W1_FunctionList!$H$10:$H$87,MATCH($B27,W1_FunctionList!$B$10:$B$87,0)),""))} -> Could | H27: =IF($B27="","",IF(G27="",D27,G27)) -> Could | J27: =IF($B27="","",SUMIF(W2_Costing!$C$9:$C$128,$B27,W2_Costing!$J$9:$J$128)) -> #N/A | K27: =IF($B27="","",SUMIF(W2_Costing!$C$9:$C$128,$B27,W2_Costing!$M$9:$M$128)) -> #N/A
A28: {=IF($B28="","",IFERROR(INDEX(W1_FunctionList!$A$10:$A$87,MATCH($B28,W1_FunctionList!$B$10:$B$87,0)),""))} -> F-02 | B28: {=IFERROR(INDEX(W1_FunctionList!$B$10:$B$87,MATCH(10,W1_FunctionList!$R$10:$R$87,0)),"")} -> FR-02-05 | C28: {=IF($B28="","",IFERROR(INDEX(W1_FunctionList!$C$10:$C$87,MATCH($B28,W1_FunctionList!$B$10:$B$87,0)),""))} -> Open book information and reviews via QR code | D28: {=IF($B28="","",IFERROR(INDEX(W1_FunctionList!$H$10:$H$87,MATCH($B28,W1_FunctionList!$B$10:$B$87,0)),""))} -> Must | H28: =IF($B28="","",IF(G28="",D28,G28)) -> Must | J28: =IF($B28="","",SUMIF(W2_Costing!$C$9:$C$128,$B28,W2_Costing!$J$9:$J$128)) -> #N/A | K28: =IF($B28="","",SUMIF(W2_Costing!$C$9:$C$128,$B28,W2_Costing!$M$9:$M$128)) -> #N/A
A29: {=IF($B29="","",IFERROR(INDEX(W1_FunctionList!$A$10:$A$87,MATCH($B29,W1_FunctionList!$B$10:$B$87,0)),""))} -> F-02 | B29: {=IFERROR(INDEX(W1_FunctionList!$B$10:$B$87,MATCH(11,W1_FunctionList!$R$10:$R$87,0)),"")} -> FR-02-06 | C29: {=IF($B29="","",IFERROR(INDEX(W1_FunctionList!$C$10:$C$87,MATCH($B29,W1_FunctionList!$B$10:$B$87,0)),""))} -> Count QR code scans | D29: {=IF($B29="","",IFERROR(INDEX(W1_FunctionList!$H$10:$H$87,MATCH($B29,W1_FunctionList!$B$10:$B$87,0)),""))} -> Should | E29: R3 Could | F29: Attractive | G29: Could | H29: =IF($B29="","",IF(G29="",D29,G29)) -> Could | I29: No reader-facing impact: scan counts only feed analysis and AI training, and the AI features are already Could. Dropping it does not block QR access (FR-02-05) or label printing (FR-02-08). | J29: =IF($B29="","",SUMIF(W2_Costing!$C$9:$C$128,$B29,W2_Costing!$J$9:$J$128)) -> #N/A | K29: =IF($B29="","",SUMIF(W2_Costing!$C$9:$C$128,$B29,W2_Costing!$M$9:$M$128)) -> #N/A
A30: {=IF($B30="","",IFERROR(INDEX(W1_FunctionList!$A$10:$A$87,MATCH($B30,W1_FunctionList!$B$10:$B$87,0)),""))} -> F-02 | B30: {=IFERROR(INDEX(W1_FunctionList!$B$10:$B$87,MATCH(12,W1_FunctionList!$R$10:$R$87,0)),"")} -> FR-02-07 | C30: {=IF($B30="","",IFERROR(INDEX(W1_FunctionList!$C$10:$C$87,MATCH($B30,W1_FunctionList!$B$10:$B$87,0)),""))} -> Generate QR codes for new physical books | D30: {=IF($B30="","",IFERROR(INDEX(W1_FunctionList!$H$10:$H$87,MATCH($B30,W1_FunctionList!$B$10:$B$87,0)),""))} -> Must | H30: =IF($B30="","",IF(G30="",D30,G30)) -> Must | J30: =IF($B30="","",SUMIF(W2_Costing!$C$9:$C$128,$B30,W2_Costing!$J$9:$J$128)) -> #N/A | K30: =IF($B30="","",SUMIF(W2_Costing!$C$9:$C$128,$B30,W2_Costing!$M$9:$M$128)) -> #N/A
A31: {=IF($B31="","",IFERROR(INDEX(W1_FunctionList!$A$10:$A$87,MATCH($B31,W1_FunctionList!$B$10:$B$87,0)),""))} -> F-02 | B31: {=IFERROR(INDEX(W1_FunctionList!$B$10:$B$87,MATCH(13,W1_FunctionList!$R$10:$R$87,0)),"")} -> FR-02-08 | C31: {=IF($B31="","",IFERROR(INDEX(W1_FunctionList!$C$10:$C$87,MATCH($B31,W1_FunctionList!$B$10:$B$87,0)),""))} -> Print QR code labels | D31: {=IF($B31="","",IFERROR(INDEX(W1_FunctionList!$H$10:$H$87,MATCH($B31,W1_FunctionList!$B$10:$B$87,0)),""))} -> Must | H31: =IF($B31="","",IF(G31="",D31,G31)) -> Must | J31: =IF($B31="","",SUMIF(W2_Costing!$C$9:$C$128,$B31,W2_Costing!$J$9:$J$128)) -> #N/A | K31: =IF($B31="","",SUMIF(W2_Costing!$C$9:$C$128,$B31,W2_Costing!$M$9:$M$128)) -> #N/A
A32: {=IF($B32="","",IFERROR(INDEX(W1_FunctionList!$A$10:$A$87,MATCH($B32,W1_FunctionList!$B$10:$B$87,0)),""))} -> F-02 | B32: {=IFERROR(INDEX(W1_FunctionList!$B$10:$B$87,MATCH(14,W1_FunctionList!$R$10:$R$87,0)),"")} -> FR-02-09 | C32: {=IF($B32="","",IFERROR(INDEX(W1_FunctionList!$C$10:$C$87,MATCH($B32,W1_FunctionList!$B$10:$B$87,0)),""))} -> Report a review that breaks the rules | D32: {=IF($B32="","",IFERROR(INDEX(W1_FunctionList!$H$10:$H$87,MATCH($B32,W1_FunctionList!$B$10:$B$87,0)),""))} -> Could | H32: =IF($B32="","",IF(G32="",D32,G32)) -> Could | J32: =IF($B32="","",SUMIF(W2_Costing!$C$9:$C$128,$B32,W2_Costing!$J$9:$J$128)) -> #N/A | K32: =IF($B32="","",SUMIF(W2_Costing!$C$9:$C$128,$B32,W2_Costing!$M$9:$M$128)) -> #N/A
A33: {=IF($B33="","",IFERROR(INDEX(W1_FunctionList!$A$10:$A$87,MATCH($B33,W1_FunctionList!$B$10:$B$87,0)),""))} -> F-02 | B33: {=IFERROR(INDEX(W1_FunctionList!$B$10:$B$87,MATCH(15,W1_FunctionList!$R$10:$R$87,0)),"")} -> FR-02-10 | C33: {=IF($B33="","",IFERROR(INDEX(W1_FunctionList!$C$10:$C$87,MATCH($B33,W1_FunctionList!$B$10:$B$87,0)),""))} -> Review and remove reported reviews | D33: {=IF($B33="","",IFERROR(INDEX(W1_FunctionList!$H$10:$H$87,MATCH($B33,W1_FunctionList!$B$10:$B$87,0)),""))} -> Could | H33: =IF($B33="","",IF(G33="",D33,G33)) -> Could | J33: =IF($B33="","",SUMIF(W2_Costing!$C$9:$C$128,$B33,W2_Costing!$J$9:$J$128)) -> #N/A | K33: =IF($B33="","",SUMIF(W2_Costing!$C$9:$C$128,$B33,W2_Costing!$M$9:$M$128)) -> #N/A
